Workbook

Sheet UFLS (Cat1&Cat2)
A1: UNDER-FREQUENCY LOAD SHEDDING (UFLS) REVISION 2024
A2: Assignment | B2: GM - Subzone | C2: Substation | D2: Mnemonic | E2: kV | F2: Assigned Feeders | G2: CB | H2: Freq1 | I2: Delay1 (s) | J2: Freq2 | K2: Delay2 (s) | L2: MW Quantum 2024 | M2: Load Area Affected | N2: UFLS 2024 Review Remarks
A3: =CONCATENATE("Stage: Ride Through " & CHAR(10) &"Total load: ",ROUND(SUM(L3:L16),0),"MW") -> Stage: Ride Through Total load: 311MW | B3: Kuantan | C3: Gebeng Industri | D3: GBID | E3: 132 | F3: KSTL 1 & 2 | G3: 105 & 405 | H3: 49.3 | I3: 0 | J3: n/a | K3: n/a | L3: 0 | M3: KSTL load
B4: Johor Bahru | C4: Tanjung Langsat | D4: TLST | E4: 132 | F4: TLTP (Titan Petrochemicals) | G4: 505 | H4: 49.3 | I4: 0 | J4: n/a | K4: n/a | L4: 26 | M4: TLTP
B5: Johor Bahru | C5: Pasir Gudang Darat | D5: PGDT | E5: 132 | F5: TTAN 1 & 2 | G5: 905 & 1005 | H5: 49.3 | I5: 0 | J5: n/a | K5: n/a | L5: 28 | M5: TTAN
B6: Johor Bahru | C6: Pasir Gudang Ind Est | D6: PGIE | E6: 132 | F6: ASTM 1 & 2 | G6: 805 & 905 | H6: 49.3 | I6: 0 | J6: n/a | K6: n/a | L6: 2 | M6: ASTM
B7: Johor Bahru | C7: Tanjung Langsat Industrial Estate | D7: TLIE | E7: 275 | F7: BSTL 1 & 2 | G7: L15 & L25 | H7: 49.3 | I7: 0 | J7: n/a | K7: n/a | L7: 7 | M7: BSTL
B8: Kuantan | C8: Tanjung Gelang | D8: TGLN | E8: 132 | F8: JDSI 1 & 2 | G8: 505 & 605 | H8: 49.3 | I8: 0 | J8: n/a | K8: n/a | L8: 0 | M8: JDSI
B9: Dungun | C9: Telok Kalong | D9: TKLG | E9: 275 | F9: Perwaja 1 & 2 | G9: L15 & L25 | H9: 49.3 | I9: 1 | J9: n/a | K9: n/a | L9: 0 | M9: PWSM
B10: Selangor | C10: Olak Lempit | D10: OLPT | E10: 275 | F10: MGST 1 & 2 | G10: L75 & L85 | H10: 49.3 | I10: 0 | J10: n/a | K10: n/a | L10: 25 | M10: MGST
B11: Selangor | C11: Bukit Raja GIS | D11: BRGS | E11: 132 | F11: ASMB 1 & 2 | G11: 11130, 11230, 11330 | H11: 49.3 | I11: 0 | J11: n/a | K11: n/a | L11: 44 | M11: ASMB
B12: Selangor | C12: Bukit Raja GIS | D12: BRGS | E12: 132 | F12: MSWK | G12: 7130, 7230 | H12: 49.3 | I12: 0 | J12: n/a | K12: n/a | L12: 60 | M12: MSWK
B13: Perda | C13: Bukit Tengah | D13: BTGH | E13: 132 | F13: SRON 2 | G13: 905 | H13: 49.3 | I13: 0 | J13: n/a | K13: n/a | L13: 50 | M13: SRON 905 only
B14: Perda | C14: Bedong | D14: BDNG | E14: 275 | F14: PWGR 1 & 2 feeders | G14: L35 & L45 | H14: 49.3 | I14: 0 | J14: n/a | K14: n/a | L14: 6 | M14: PWGR
B15: Perda | C15: Prai Industrial | D15: PRID | E15: 132 | F15: SRON & SRNW | G15: 505 & 605 | H15: 49.3 | I15: 0 | J15: n/a | K15: n/a | L15: 17 | M15: SRON & SRNW
B16: Perda | C16: SKS Prai | D16: SKSP | E16: 132 | F16: MWTA 1 & 2 | G16: 105 & 205 | H16: 49.3 | I16: 0 | J16: n/a | K16: n/a | L16: 46 | M16: MWTA
A17: =CONCATENATE("Stage 1: 49.2Hz " & CHAR(10) &"Total load: ",ROUND(SUM(L17:L37),0),"MW") -> Stage 1: 49.2Hz Total load: 1001MW | B17: Johor Bahru | C17: Cahaya Baru | D17: CBRU | E17: 22 | F17: 132/22kV T1 & T2 | G17: 1T0 & 2T0 | H17: 49.2 | I17: 0 | J17: n/a | K17: n/a | L17: 21.3659 | M17: CBRU 22kV
B18: Johor Bahru | C18: Pasir Gudang Darat | D18: PGDT | E18: 22 | F18: 132/22kV T1 & T2 | G18: 1T0 & 2T0 | H18: 49.2 | I18: 0 | J18: n/a | K18: n/a | L18: 21.8789 | M18: PGDT 22kV
B19: Johor Bahru | C19: Tampoi Industries | D19: TMPI | E19: 33 | F19: 132/33kV T1 & T2 | G19: 1T0 & 2T0 | H19: 49.2 | I19: 0 | J19: n/a | K19: n/a | L19: 64.0768 | M19: TMPI 33kV
B20: Perda | C20: Sungai Ara (GIS) | D20: SARA | E20: 33 | F20: 132/33kV T1 & T2 | G20: 1T0 & 2T0 | H20: 49.2 | I20: 0 | J20: n/a | K20: n/a | L20: 41.5461 | M20: SARA 33kV
B21: Kuantan | C21: Pekan Industri AIP | D21: PKNI | E21: 33 | F21: 132/33kV T1 & T2 | G21: 1T0 & 2T1 | H21: 49.2 | I21: 0 | J21: n/a | K21: n/a | L21: 18.5562 | M21: PKNI 33kV
B22: Ayer Keroh | C22: Hicom Pegoh | D22: HPGH | E22: 33 | F22: 132/33kV T1 & T2 | G22: 1T0 & 2T0 | H22: 49.2 | I22: 0 | J22: n/a | K22: n/a | L22: 15.3861 | M22: HPGH 33kV
B23: Seremban | C23: Enstek | D23: ESTK | E23: 33 | F23: 132/33kV T1 & T2 | G23: 1T0 & 2T0 | H23: 49.2 | I23: 0 | J23: n/a | K23: n/a | L23: 36.4197 | M23: ESTK 33kV
B24: Seremban | C24: Kg. Repah | D24: KRPH | E24: 11 | F24: 132/11kV T1 & T2 | G24: 30 & 32 | H24: 49.2 | I24: 0 | J24: n/a | K24: n/a | L24: 20.2233 | M24: KRPH 11kV
B25: Ipoh | C25: Pengkalan Industri | D25: PKID | E25: 11 | F25: 132/11kV T1 & T2 | G25: 31 & 32 | H25: 49.2 | I25: 0 | J25: n/a | K25: n/a | L25: 21.5372 | M25: PKID 11kV
B26: Ipoh | C26: Pengkalan Industri | D26: PKID | E26: 33 | F26: 132/33kV T3 & T4 | G26: 3T0 & 4T0 | H26: 49.2 | I26: 0 | J26: n/a | K26: n/a | L26: 25.2821 | M26: PKID 33kV
B27: Ipoh | C27: Kinta Valley Resort | D27: KVRT | E27: 33 | F27: 132/33kV T3 & T4 | G27: 3T0, 4T0 & 1W0 | H27: 49.2 | I27: 0 | J27: n/a | K27: n/a | L27: 61.5771 | M27: KVRT 33 kV
B28: Ipoh | C28: Menglembu | D28: MLBU | E28: 33 | F28: 132/33kV T3 & T4 | G28: 3T0 & 4T0 | H28: 49.2 | I28: 0 | J28: n/a | K28: n/a | L28: 83.9211 | M28: MLBU 33kV
B29: Selangor | C29: Setia Alam | D29: STIA | E29: 33 | F29: 132/33kV T1 & T2 | G29: 1T0 & 2T1 | H29: 49.2 | I29: 0 | J29: n/a | K29: n/a | L29: 76.0234 | M29: STIA 33kV
... B37: Alor Setar | C37: Pauh | D37: PAUH | E37: 33 | F37: 132/33kV T1 & T2 | G37: 1T0 & 2T0 | H37: 49.2 | I37: 0 | J37: n/a | K37: n/a | L37: 42.691 | M37: PAUH 33kV
A38: =CONCATENATE("Stage 2: 49.1Hz " & CHAR(10) &"Total load: ",ROUND(SUM(L38:L56),0),"MW") -> Stage 2: 49.1Hz Total load: 801MW | B38: Ipoh | C38: Temoh | D38: TMOH | E38: 33 | F38: 132/33kV T3 & T4 | G38: 3T0 & 4T0 | H38: 49.1 | I38: 0 | J38: n/a | K38: n/a | L38: 22.3732 | M38: TMOH 33kV
B39: Ipoh | C39: Kelebang | D39: KLBG | E39: 33 | F39: 132/33kV T3 & T4 | G39: 3T0, 4T0 & 1W0 | H39: 49.1 | I39: 0 | J39: n/a | K39: n/a | L39: 24.6724 | M39: KLBG 33kV
B40: Ipoh | C40: New Khantan | D40: NKAN | E40: 33 | F40: 132/33kV T1 & T2 | G40: 1T0 & 2T0 | H40: 49.1 | I40: 0 | J40: n/a | K40: n/a | L40: 32.1433 | M40: NKAN 33kV
B41: Ipoh | C41: Tasik | D41: TASK | E41: 33 | F41: 132/33kV T1 & T2 | G41: 1T0 & 2T0 | H41: 49.1 | I41: 0 | J41: n/a | K41: n/a | L41: 8.5343 | M41: TASK 22kV
B42: Kuala Lumpur | C42: SPPK Cheras | D42: SPKC | E42: 33 | F42: 132/33kV T3 & T4 & T5 | G42: 3T0 & 4T0 & 1W0 & 5T0 | H42: 49.1 | I42: 0 | J42: n/a | K42: n/a | L42: 123.2475 | M42: SPKC 33kV
B43: Kuala Lumpur | C43: National University | D43: NUNI | E43: 11 | F43: 132/11kV T1 & T2 | G43: 31 & 32 | H43: 49.1 | I43: 0 | J43: n/a | K43: n/a | L43: 24.5161 | M43: NUNI 11kV
B44: Johor Bahru | C44: Plentong | D44: PLTG | E44: 230 | F44: WAV8 1 & 2 | G44: H10 & H20 | H44: 49.1 | I44: 0 | J44: n/a | K44: n/a | L44: - | M44: TNB-Singapore Interconnection
B45: Johor Bahru | C45: Tebrau | D45: TBRU | E45: 22 | F45: 132/22kV T1 & T2 | G45: 1T0 & 2T0 | H45: 49.1 | I45: 0 | J45: n/a | K45: n/a | L45: 29.3428 | M45: TBRU 22kV
B46: Kuantan | C46: Kampung Awah | D46: KAWA | E46: 132 | F46: KRYG 1 & 2 | G46: 305 & 405 | H46: 49.1 | I46: 0 | J46: n/a | K46: n/a | L46: 30 | M46: KRYG
B47: Seremban | C47: Tuanku Jaafar (GIS) | D47: TJGS | E47: 132 | F47: SHEL 1 & 2 | G47: 505 & 605 | H47: 49.1 | I47: 0 | J47: n/a | K47: n/a | L47: 36 | M47: SHELL
...

Sheet UFLS (Cat3 Deactivate)
A1: UNDER-FREQUENCY LOAD SHEDDING (UFLS) REVISION 2024
A2: GM - Subzone | B2: Substation | C2: Mnemonic | D2: kV | E2: Assigned Feeders | F2: CB | G2: UFLS 2024 Review Remarks
A3: Dungun | B3: Telok Kalong | C3: TKLG | D3: 275 | E3: ESTL 1 & 2 | F3: L95 & L105 | G3: Deactivate for the latest 2024 review
A4: Kota Bharu | B4: Tanah Merah | C4: TMRH | D4: 132 | E4: KKRI 1&2 | F4: 505 & 605 | G4: Deactivate for latest the 2024 review due to LSS MALS and the future Nenggiri Power Station in the pocket load
A5: Melaka | B5: Ujong Pasir | C5: UPSR | D5: 132 | E5: AKRH & AKRH/ONST | F5: 105 & 205 | G5: Deactivate for latest the 2024 review due to LSS JSLS in the pocket load
A6: Kuala Lumpur | B6: Bandar Tun Razak | C6: BTRZ | D6: 33 | E6: 132/33kV T3 & T4 | F6: 3T0 & 4T0 & 1W0 | G6: Deactivate. Supplying to essential loads - TNB/GSO/GSM/GST/3/1 (UFLS/UVLS) dated 19 Aug 2022
A7: Kuala Lumpur | B7: KL City Centre | C7: KLCC | D7: 11 | E7: 132/11kV T1 & T2 | F7: 31 & 32 | G7: Deactivate. Supplying to essential loads - TNB/GSO/GSM/GST/3/1 (UFLS/UVLS) dated 19 Aug 2022
A8: Kuala Lumpur | B8: Putrajaya | C8: PJYC | D8: 33 | E8: 132/33kV T1 & T2 | F8: 1T0 & 2T0 | G8: Deactivate. Supplying to essential loads - TNB/GSO/GSM/GST/3/1 (UFLS/UVLS) dated Nov 2022
A9: Perda | B9: Bukit Merah | C9: BMRH | D9: 132 | E9: BSRI 1 & 2 | F9: 305 & 405 | G9: Deactivate for latest the 2024 review due to LSS KNLS in the pocket load
A10: Perda | B10: Bayan Lepas | C10: BLPS | D10: 33 | E10: 132/33kV T1 & T2 | F10: 1T0 & 2T0 | G10: Deactivate. Supplying to essential loads - TNB/GSO/GSM/GST/3/1 (UFLS/UVLS) dated 19 Aug 2022
A11: Perda | B11: Bayan Lepas | C11: BLPS | D11: 33 | E11: 132/33kV T3 & T5 | F11: 3T0 & 4T0 | G11: Deactivate. Supplying to essential loads - TNB/GSO/GSM/GST/3/1 (UFLS/UVLS) dated 19 Aug 2022
A12: Perda | B12: Bayan Baru | C12: BBRU | D12: 33 | E12: 132/33kV T1 & T2 | F12: 1T0 & 2T0 | G12: Deactivate. Supplying to essential loads - TNB/GSO/GSM/GST/3/1 (UFLS/UVLS) dated 19 Aug 2022
A13: Perda | B13: Bedong | C13: BDNG | D13: 132 | E13: SPID & AJYA | F13: 105 & 205 | G13: Deactivate. Supplying to essential loads - TNB/GSO/GSM/GST/3/1 (UFLS/UVLS) dated 19 Aug 2022
A14: Kuala Lumpur | B14: Kajang | C14: KJNG | D14: 33 | E14: 132/33kV T3 & T4 | F14: 3T0 & 4T0 | G14: Deactivate. Supplying to essential loads - TNB/GSO/GSM/GST/3/1 (UFLS/UVLS) dated 6 April 2020
... A30: Kuantan | B30: Kuantan | C30: KTAN | D30: 132 | E30: KTNN feeders | F30: 305 & 405 | G30: Deactivate. Supplying to essential loads - TNB/GSO/GSM/GST/3/1 (UFLS/UVLS) dated 6 April 2020

Sheet ActiveAll_UFLS&UVLS
A1: UNDER-FREQUENCY LOAD SHEDDING (UFLS) | O1: UNDER-VOLTAGE LOAD SHEDDING (UVLS)
A2: Assignment | B2: GM - Subzone | C2: Substation | D2: Mnemonic | E2: kV | F2: Assigned Feeders | G2: CB | H2: Freq1 | I2: Delay1 (s) | J2: Freq2 | K2: Delay2 (s) | L2: MW Quantum 2024 | M2: Load Area Affected | N2: UFLS 2024 Review Remarks | O2: Voltage pickup setting (p.u) | P2: Delay (s) | Q2: UVLS Operating Stage
A3: Stage: Ride Through | B3: Kuantan | C3: Gebeng Industri | D3: GBID | E3: 132 | F3: KSTL 1 & 2 | G3: 105 & 405 | H3: 49.3 | I3: 0 | J3: n/a | K3: n/a | L3: 0 | M3: KSTL load
A4: Stage: Ride Through | B4: Johor Bahru | C4: Tanjung Langsat | D4: TLST | E4: 132 | F4: TLTP (Titan Petrochemicals) | G4: 505 | H4: 49.3 | I4: 0 | J4: n/a | K4: n/a | L4: 26 | M4: TLTP
A5: Stage: Ride Through | B5: Johor Bahru | C5: Pasir Gudang Darat | D5: PGDT | E5: 132 | F5: TTAN 1 & 2 | G5: 905 & 1005 | H5: 49.3 | I5: 0 | J5: n/a | K5: n/a | L5: 28 | M5: TTAN
A6: Stage: Ride Through | B6: Johor Bahru | C6: Pasir Gudang Ind Est | D6: PGIE | E6: 132 | F6: ASTM 1 & 2 | G6: 805 & 905 | H6: 49.3 | I6: 0 | J6: n/a | K6: n/a | L6: 2 | M6: ASTM
A7: Stage: Ride Through | B7: Johor Bahru | C7: Tanjung Langsat Industrial Estate | D7: TLIE | E7: 275 | F7: BSTL 1 & 2 | G7: L15 & L25 | H7: 49.3 | I7: 0 | J7: n/a | K7: n/a | L7: 7 | M7: BSTL
A8: Stage: Ride Through | B8: Kuantan | C8: Tanjung Gelang | D8: TGLN | E8: 132 | F8: JDSI 1 & 2 | G8: 505 & 605 | H8: 49.3 | I8: 0 | J8: n/a | K8: n/a | L8: 0 | M8: JDSI
A9: Stage: Ride Through | B9: Dungun | C9: Telok Kalong | D9: TKLG | E9: 275 | F9: Perwaja 1 & 2 | G9: L15 & L25 | H9: 49.3 | I9: 1 | J9: n/a | K9: n/a | L9: 0 | M9: PWSM
A10: Stage: Ride Through | B10: Selangor | C10: Olak Lempit | D10: OLPT | E10: 275 | F10: MGST 1 & 2 | G10: L75 & L85 | H10: 49.3 | I10: 0 | J10: n/a | K10: n/a | L10: 25 | M10: MGST
A11: Stage: Ride Through | B11: Selangor | C11: Bukit Raja GIS | D11: BRGS | E11: 132 | F11: ASMB 1 & 2 | G11: 11130, 11230, 11330 | H11: 49.3 | I11: 0 | J11: n/a | K11: n/a | L11: 44 | M11: ASMB
A12: Stage: Ride Through | B12: Selangor | C12: Bukit Raja GIS | D12: BRGS | E12: 132 | F12: MSWK | G12: 7130, 7230 | H12: 49.3 | I12: 0 | J12: n/a | K12: n/a | L12: 60 | M12: MSWK
A13: Stage: Ride Through | B13: Perda | C13: Bukit Tengah | D13: BTGH | E13: 132 | F13: SRON 2 | G13: 905 | H13: 49.3 | I13: 0 | J13: n/a | K13: n/a | L13: 50 | M13: SRON 905 only
A14: Stage: Ride Through | B14: Perda | C14: Bedong | D14: BDNG | E14: 275 | F14: PWGR 1 & 2 feeders | G14: L35 & L45 | H14: 49.3 | I14: 0 | J14: n/a | K14: n/a | L14: 6 | M14: PWGR
A15: Stage: Ride Through | B15: Perda | C15: Prai Industrial | D15: PRID | E15: 132 | F15: SRON & SRNW | G15: 505 & 605 | H15: 49.3 | I15: 0 | J15: n/a | K15: n/a | L15: 17 | M15: SRON & SRNW
A16: Stage: Ride Through | B16: Perda | C16: SKS Prai | D16: SKSP | E16: 132 | F16: MWTA 1 & 2 | G16: 105 & 205 | H16: 49.3 | I16: 0 | J16: n/a | K16: n/a | L16: 46 | M16: MWTA
A17: Stage 1: 49.2Hz | B17: Johor Bahru | C17: Cahaya Baru | D17: CBRU | E17: 22 | F17: 132/22kV T1 & T2 | G17: 1T0 & 2T0 | H17: 49.2 | I17: 0 | J17: n/a | K17: n/a | L17: 21.3659 | M17: CBRU 22kV
A18: Stage 1: 49.2Hz | B18: Johor Bahru | C18: Pasir Gudang Darat | D18: PGDT | E18: 22 | F18: 132/22kV T1 & T2 | G18: 1T0 & 2T0 | H18: 49.2 | I18: 0 | J18: n/a | K18: n/a | L18: 21.8789 | M18: PGDT 22kV
A19: Stage 1: 49.2Hz | B19: Johor Bahru | C19: Tampoi Industries | D19: TMPI | E19: 33 | F19: 132/33kV T1 & T2 | G19: 1T0 & 2T0 | H19: 49.2 | I19: 0 | J19: n/a | K19: n/a | L19: 64.0768 | M19: TMPI 33kV
A20: Stage 1: 49.2Hz | B20: Perda | C20: Sungai Ara (GIS) | D20: SARA | E20: 33 | F20: 132/33kV T1 & T2 | G20: 1T0 & 2T0 | H20: 49.2 | I20: 0 | J20: n/a | K20: n/a | L20: 41.5461 | M20: SARA 33kV
A21: Stage 1: 49.2Hz | B21: Kuantan | C21: Pekan Industri AIP | D21: PKNI | E21: 33 | F21: 132/33kV T1 & T2 | G21: 1T0 & 2T1 | H21: 49.2 | I21: 0 | J21: n/a | K21: n/a | L21: 18.5562 | M21: PKNI 33kV
A22: Stage 1: 49.2Hz | B22: Ayer Keroh | C22: Hicom Pegoh | D22: HPGH | E22: 33 | F22: 132/33kV T1 & T2 | G22: 1T0 & 2T0 | H22: 49.2 | I22: 0 | J22: n/a | K22: n/a | L22: 15.3861 | M22: HPGH 33kV
A23: Stage 1: 49.2Hz | B23: Seremban | C23: Enstek | D23: ESTK | E23: 33 | F23: 132/33kV T1 & T2 | G23: 1T0 & 2T0 | H23: 49.2 | I23: 0 | J23: n/a | K23: n/a | L23: 36.4197 | M23: ESTK 33kV
A24: Stage 1: 49.2Hz | B24: Seremban | C24: Kg. Repah | D24: KRPH | E24: 11 | F24: 132/11kV T1 & T2 | G24: 30 & 32 | H24: 49.2 | I24: 0 | J24: n/a | K24: n/a | L24: 20.2233 | M24: KRPH 11kV
A25: Stage 1: 49.2Hz | B25: Ipoh | C25: Pengkalan Industri | D25: PKID | E25: 11 | F25: 132/11kV T1 & T2 | G25: 31 & 32 | H25: 49.2 | I25: 0 | J25: n/a | K25: n/a | L25: 21.5372 | M25: PKID 11kV
... A30: Stage 1: 49.2Hz | B30: Kuala Lumpur | C30: Damansara City | D30: DCTY | E30: 33 | F30: 132/33kV T1 & T2 | G30: 1T0 & 2T0 | H30: 49.2 | I30: 0 | J30: n/a | K30: n/a | L30: 28.4475 | M30: DCTY 33kV
A31: Stage 1: 49.2Hz | B31: Kuala Lumpur | C31: Manjalara | D31: MJLR | E31: 33 | F31: 132/33kV T1 & T2 | G31: 1T0 & 2T0 | H31: 49.2 | I31: 0 | J31: n/a | K31: n/a | L31: 89.8683 | M31: MJLR 33kV | O31: 0.9 | P31: 30 | Q31: 1
A32: Stage 1: 49.2Hz | B32: Kuala Lumpur | C32: Sri Hartamas | D32: SHMS | E32: 33 | F32: 132/33kV T1 & T2 | G32: 1T0 & 2T0 | H32: 49.2 | I32: 0 | J32: n/a | K32: n/a | L32: 71.0055 | M32: SHMS 33kV
A33: Stage 1: 49.2Hz | B33: Kuala Lumpur | C33: Suncity GIS | D33: SCTY | E33: 33 | F33: 132/33kV T1 & T2 | G33: 1T0 & 2T2 | H33: 49.2 | I33: 0 | J33: n/a | K33: n/a | L33: 25.6995 | M33: SCTY 33kV
A34: Stage 1: 49.2Hz | B34: Kuala Lumpur | C34: Cheras Jaya | D34: CJYA | E34: 33 | F34: 132/33kV T1, T2 & T3 | G34: 1T0 & 2T0 & 3T0 | H34: 49.2 | I34: 0 | J34: n/a | K34: n/a | L34: 157.1371 | M34: CJYA 33kV
A35: Stage 1: 49.2Hz | B35: Kuala Lumpur | C35: Danau Desa | D35: DDSA | E35: 33 | F35: 132/33kV T3 & T4 | G35: 3T0 & 4T0 | H35: 49.2 | I35: 0 | J35: n/a | K35: n/a | L35: 60.7924 | M35: DDSA 33kV
A36: Stage 1: 49.2Hz | B36: Alor Setar | C36: Mergong | D36: MGON | E36: 11 | F36: 132/11kV T1 & T2 | G36: 31 & 32 | H36: 49.2 | I36: 0 | J36: n/a | K36: n/a | L36: 17.2107 | M36: MGON 11kV
A37: Stage 1: 49.2Hz | B37: Alor Setar | C37: Pauh | D37: PAUH | E37: 33 | F37: 132/33kV T1 & T2 | G37: 1T0 & 2T0 | H37: 49.2 | I37: 0 | J37: n/a | K37: n/a | L37: 42.691 | M37: PAUH 33kV
A38: Stage 2: 49.1Hz | B38: Ipoh | C38: Temoh | D38: TMOH | E38: 33 | F38: 132/33kV T3 & T4 | G38: 3T0 & 4T0 | H38: 49.1 | I38: 0 | J38: n/a | K38: n/a | L38: 22.3732 | M38: TMOH 33kV
A39: Stage 2: 49.1Hz | B39: Ipoh | C39: Kelebang | D39: KLBG | E39: 33 | F39: 132/33kV T3 & T4 | G39: 3T0, 4T0 & 1W0 | H39: 49.1 | I39: 0 | J39: n/a | K39: n/a | L39: 24.6724 | M39: KLBG 33kV
A40: Stage 2: 49.1Hz | B40: Ipoh | C40: New Khantan | D40: NKAN | E40: 33 | F40: 132/33kV T1 & T2 | G40: 1T0 & 2T0 | H40: 49.1 | I40: 0 | J40: n/a | K40: n/a | L40: 32.1433 | M40: NKAN 33kV
A41: Stage 2: 49.1Hz | B41: Ipoh | C41: Tasik | D41: TASK | E41: 33 | F41: 132/33kV T1 & T2 | G41: 1T0 & 2T0 | H41: 49.1 | I41: 0 | J41: n/a | K41: n/a | L41: 8.5343 | M41: TASK 22kV
A42: Stage 2: 49.1Hz | B42: Kuala Lumpur | C42: SPPK Cheras | D42: SPKC | E42: 33 | F42: 132/33kV T3 & T4 & T5 | G42: 3T0 & 4T0 & 1W0 & 5T0 | H42: 49.1 | I42: 0 | J42: n/a | K42: n/a | L42: 123.2475 | M42: SPKC 33kV
A43: Stage 2: 49.1Hz | B43: Kuala Lumpur | C43: National University | D43: NUNI | E43: 11 | F43: 132/11kV T1 & T2 | G43: 31 & 32 | H43: 49.1 | I43: 0 | J43: n/a | K43: n/a | L43: 24.5161 | M43: NUNI 11kV
A44: Stage 2: 49.1Hz | B44: Johor Bahru | C44: Plentong | D44: PLTG | E44: 230 | F44: WA18 1 & 2 | G44: H10 & H20 | H44: 49.1 | I44: 0 | J44: n/a | K44: n/a | L44: - | M44: TNB-Singapore Interconnection
...

Sheet UFLS_review
A1: UNDER-FREQUENCY LOAD SHEDDING (UFLS) | Q1: UNDER-VOLTAGE LOAD SHEDDING (UVLS)
A2: Assignment | B2: GM - Subzone | C2: Substation | D2: Mnemonic | E2: kV | F2: Assigned Feeders | G2: CB | H2: Freq1 | I2: Delay1 (s) | J2: Freq2 | K2: Delay2 (s) | L2: MW Quantum 2024 | M2: MW Quantum 2025 | N2: Load Area Affected | P2: UFLS 2024 Review Remarks | Q2: Voltage pickup setting (p.u) | R2: Delay (s) | S2: UVLS Operating Stage
A3: Stage: Ride Through | B3: Kuantan | C3: Gebeng Industri | D3: GBID | E3: 132 | F3: KSTL 1 & 2 | G3: 105 & 405 | H3: 49.3 | I3: 0 | J3: n/a | K3: n/a | L3: 0 | N3: KSTL load
A4: Stage: Ride Through | B4: Johor Bahru | C4: Tanjung Langsat | D4: TLST | E4: 132 | F4: TLTP (Titan Petrochemicals) | G4: 505 | H4: 49.3 | I4: 0 | J4: n/a | K4: n/a | L4: 26 | N4: TLTP
A5: Stage: Ride Through | B5: Johor Bahru | C5: Pasir Gudang Darat | D5: PGDT | E5: 132 | F5: TTAN 1 & 2 | G5: 905 & 1005 | H5: 49.3 | I5: 0 | J5: n/a | K5: n/a | L5: 28 | N5: TTAN
A6: Stage: Ride Through | B6: Johor Bahru | C6: Pasir Gudang Ind Est | D6: PGIE | E6: 132 | F6: ASTM 1 & 2 | G6: 805 & 905 | H6: 49.3 | I6: 0 | J6: n/a | K6: n/a | L6: 2 | N6: ASTM
A7: Stage: Ride Through | B7: Johor Bahru | C7: Tanjung Langsat Industrial Estate | D7: TLIE | E7: 275 | F7: BSTL 1 & 2 | G7: L15 & L25 | H7: 49.3 | I7: 0 | J7: n/a | K7: n/a | L7: 7 | N7: BSTL
A8: Stage: Ride Through | B8: Kuantan | C8: Tanjung Gelang | D8: TGLN | E8: 132 | F8: JDSI 1 & 2 | G8: 505 & 605 | H8: 49.3 | I8: 0 | J8: n/a | K8: n/a | L8: 0 | N8: JDSI
A9: Stage: Ride Through | B9: Dungun | C9: Telok Kalong | D9: TKLG | E9: 275 | F9: Perwaja 1 & 2 | G9: L15 & L25 | H9: 49.3 | I9: 1 | J9: n/a | K9: n/a | L9: 0 | N9: PWSM
A10: Stage: Ride Through | B10: Selangor | C10: Olak Lempit | D10: OLPT | E10: 275 | F10: MGST 1 & 2 | G10: L75 & L85 | H10: 49.3 | I10: 0 | J10: n/a | K10: n/a | L10: 25 | N10: MGST
A11: Stage: Ride Through | B11: Selangor | C11: Bukit Raja GIS | D11: BRGS | E11: 132 | F11: ASMB 1 & 2 | G11: 11130, 11230, 11330 | H11: 49.3 | I11: 0 | J11: n/a | K11: n/a | L11: 44 | N11: ASMB
A12: Stage: Ride Through | B12: Selangor | C12: Bukit Raja GIS | D12: BRGS | E12: 132 | F12: MSWK | G12: 7130, 7230 | H12: 49.3 | I12: 0 | J12: n/a | K12: n/a | L12: 60 | N12: MSWK
A13: Stage: Ride Through | B13: Perda | C13: Bukit Tengah | D13: BTGH | E13: 132 | F13: SRON 2 | G13: 905 | H13: 49.3 | I13: 0 | J13: n/a | K13: n/a | L13: 50 | N13: SRON 905 only
A14: Stage: Ride Through | B14: Perda | C14: Bedong | D14: BDNG | E14: 275 | F14: PWGR 1 & 2 feeders | G14: L35 & L45 | H14: 49.3 | I14: 0 | J14: n/a | K14: n/a | L14: 6 | N14: PWGR
A15: Stage: Ride Through | B15: Perda | C15: Prai Industrial | D15: PRID | E15: 132 | F15: SRON & SRNW | G15: 505 & 605 | H15: 49.3 | I15: 0 | J15: n/a | K15: n/a | L15: 17 | N15: SRON & SRNW
A16: Stage: Ride Through | B16: Perda | C16: SKS Prai | D16: SKSP | E16: 132 | F16: MWTA 1 & 2 | G16: 105 & 205 | H16: 49.3 | I16: 0 | J16: n/a | K16: n/a | L16: 46 | N16: MWTA
A17: Stage 1: 49.2Hz | B17: Johor Bahru | C17: Cahaya Baru | D17: CBRU | E17: 22 | F17: 132/22kV T1 & T2 | G17: 1T0 & 2T0 | H17: 49.2 | I17: 0 | J17: n/a | K17: n/a | L17: 21.3659 | N17: CBRU 22kV
A18: Stage 1: 49.2Hz | B18: Johor Bahru | C18: Pasir Gudang Darat | D18: PGDT | E18: 22 | F18: 132/22kV T1 & T2 | G18: 1T0 & 2T0 | H18: 49.2 | I18: 0 | J18: n/a | K18: n/a | L18: 21.8789 | N18: PGDT 22kV
A19: Stage 1: 49.2Hz | B19: Johor Bahru | C19: Tampoi Industries | D19: TMPI | E19: 33 | F19: 132/33kV T1 & T2 | G19: 1T0 & 2T0 | H19: 49.2 | I19: 0 | J19: n/a | K19: n/a | L19: 64.0768 | N19: TMPI 33kV
A20: Stage 1: 49.2Hz | B20: Perda | C20: Sungai Ara (GIS) | D20: SARA | E20: 33 | F20: 132/33kV T1 & T2 | G20: 1T0 & 2T0 | H20: 49.2 | I20: 0 | J20: n/a | K20: n/a | L20: 41.5461 | N20: SARA 33kV
A21: Stage 1: 49.2Hz | B21: Kuantan | C21: Pekan Industri AIP | D21: PKNI | E21: 33 | F21: 132/33kV T1 & T2 | G21: 1T0 & 2T1 | H21: 49.2 | I21: 0 | J21: n/a | K21: n/a | L21: 18.5562 | N21: PKNI 33kV
A22: Stage 1: 49.2Hz | B22: Ayer Keroh | C22: Hicom Pegoh | D22: HPGH | E22: 33 | F22: 132/33kV T1 & T2 | G22: 1T0 & 2T0 | H22: 49.2 | I22: 0 | J22: n/a | K22: n/a | L22: 15.3861 | N22: HPGH 33kV
A23: Stage 1: 49.2Hz | B23: Seremban | C23: Enstek | D23: ESTK | E23: 33 | F23: 132/33kV T1 & T2 | G23: 1T0 & 2T0 | H23: 49.2 | I23: 0 | J23: n/a | K23: n/a | L23: 36.4197 | N23: ESTK 33kV
A24: Stage 1: 49.2Hz | B24: Seremban | C24: Kg. Repah | D24: KRPH | E24: 11 | F24: 132/11kV T1 & T2 | G24: 30 & 32 | H24: 49.2 | I24: 0 | J24: n/a | K24: n/a | L24: 20.2233 | N24: KRPH 11kV
A25: Stage 1: 49.2Hz | B25: Ipoh | C25: Pengkalan Industri | D25: PKID | E25: 11 | F25: 132/11kV T1 & T2 | G25: 31 & 32 | H25: 49.2 | I25: 0 | J25: n/a | K25: n/a | L25: 21.5372 | N25: PKID 11kV
... A30: Stage 1: 49.2Hz | B30: Kuala Lumpur | C30: Damansara City | D30: DCTY | E30: 33 | F30: 132/33kV T1 & T2 | G30: 1T0 & 2T0 | H30: 49.2 | I30: 0 | J30: n/a | K30: n/a | L30: 28.4475 | N30: DCTY 33kV
A31: Stage 1: 49.2Hz | B31: Kuala Lumpur | C31: Manjalara | D31: MJLR | E31: 33 | F31: 132/33kV T1 & T2 | G31: 1T0 & 2T0 | H31: 49.2 | I31: 0 | J31: n/a | K31: n/a | L31: 89.8683 | N31: MJLR 33kV | Q31: 0.9 | R31: 30 | S31: 1
A32: Stage 1: 49.2Hz | B32: Kuala Lumpur | C32: Sri Hartamas | D32: SHMS | E32: 33 | F32: 132/33kV T1 & T2 | G32: 1T0 & 2T0 | H32: 49.2 | I32: 0 | J32: n/a | K32: n/a | L32: 71.0055 | N32: SHMS 33kV
A33: Stage 1: 49.2Hz | B33: Kuala Lumpur | C33: Suncity GIS | D33: SCTY | E33: 33 | F33: 132/33kV T1 & T2 | G33: 1T0 & 2T2 | H33: 49.2 | I33: 0 | J33: n/a | K33: n/a | L33: 25.6995 | N33: SCTY 33kV
A34: Stage 1: 49.2Hz | B34: Kuala Lumpur | C34: Cheras Jaya | D34: CJYA | E34: 33 | F34: 132/33kV T1, T2 & T3 | G34: 1T0 & 2T0 & 3T0 | H34: 49.2 | I34: 0 | J34: n/a | K34: n/a | L34: 157.1371 | N34: CJYA 33kV
A35: Stage 1: 49.2Hz | B35: Kuala Lumpur | C35: Danau Desa | D35: DDSA | E35: 33 | F35: 132/33kV T3 & T4 | G35: 3T0 & 4T0 | H35: 49.2 | I35: 0 | J35: n/a | K35: n/a | L35: 60.7924 | N35: DDSA 33kV
A36: Stage 1: 49.2Hz | B36: Alor Setar | C36: Mergong | D36: MGON | E36: 11 | F36: 132/11kV T1 & T2 | G36: 31 & 32 | H36: 49.2 | I36: 0 | J36: n/a | K36: n/a | L36: 17.2107 | N36: MGON 11kV
A37: Stage 1: 49.2Hz | B37: Alor Setar | C37: Pauh | D37: PAUH | E37: 33 | F37: 132/33kV T1 & T2 | G37: 1T0 & 2T0 | H37: 49.2 | I37: 0 | J37: n/a | K37: n/a | L37: 42.691 | N37: PAUH 33kV
A38: Stage 2: 49.1Hz | B38: Ipoh | C38: Temoh | D38: TMOH | E38: 33 | F38: 132/33kV T3 & T4 | G38: 3T0 & 4T0 | H38: 49.1 | I38: 0 | J38: n/a | K38: n/a | L38: 22.3732 | N38: TMOH 33kV
A39: Stage 2: 49.1Hz | B39: Ipoh | C39: Kelebang | D39: KLBG | E39: 33 | F39: 132/33kV T3 & T4 | G39: 3T0, 4T0 & 1W0 | H39: 49.1 | I39: 0 | J39: n/a | K39: n/a | L39: 24.6724 | N39: KLBG 33kV
A40: Stage 2: 49.1Hz | B40: Ipoh | C40: New Khantan | D40: NKAN | E40: 33 | F40: 132/33kV T1 & T2 | G40: 1T0 & 2T0 | H40: 49.1 | I40: 0 | J40: n/a | K40: n/a | L40: 32.1433 | N40: NKAN 33kV
A41: Stage 2: 49.1Hz | B41: Ipoh | C41: Tasik | D41: TASK | E41: 33 | F41: 132/33kV T1 & T2 | G41: 1T0 & 2T0 | H41: 49.1 | I41: 0 | J41: n/a | K41: n/a | L41: 8.5343 | N41: TASK 22kV
A42: Stage 2: 49.1Hz | B42: Kuala Lumpur | C42: SPPK Cheras | D42: SPKC | E42: 33 | F42: 132/33kV T3 & T4 & T5 | G42: 3T0 & 4T0 & 1W0 & 5T0 | H42: 49.1 | I42: 0 | J42: n/a | K42: n/a | L42: 123.2475 | N42: SPKC 33kV
A43: Stage 2: 49.1Hz | B43: Kuala Lumpur | C43: National University | D43: NUNI | E43: 11 | F43: 132/11kV T1 & T2 | G43: 31 & 32 | H43: 49.1 | I43: 0 | J43: n/a | K43: n/a | L43: 24.5161 | N43: NUNI 11kV
A44: Stage 2: 49.1Hz | B44: Johor Bahru | C44: Plentong | D44: PLTG | E44: 230 | F44: WA18 1 & 2 | G44: H10 & H20 | H44: 49.1 | I44: 0 | J44: n/a | K44: n/a | L44: - | N44: TNB-Singapore Interconnection
...

Sheet TNB Load
A1: Bus Number | B1: Bus Name | D1: Id | E1: Zone Num | F1: Zone Name | G1: Owner Num | H1: Owner Name | I1: In Service | J1: Pload (MW) | K1: Qload (Mvar)
A2: 63177 | B2: AYTH132 132.00 | C2: =LEFT(B2,4) -> AYTH | D2: T7 | E2: 1 | F2: PERLIS | G2: 1 | H2: TNB T | I2: 1 | J2: 11.6897 | K2: 4.0861
A3: 61123 | B3: BKRS132 132.00 | C3: =LEFT(B3,4) -> BKRS | D3: T1 | E3: 1 | F3: PERLIS | G3: 1 | H3: TNB T | I3: 1 | J3: 21.2899 | K3: 0.2278
A4: 61123 | B4: BKRS132 132.00 | C4: =LEFT(B4,4) -> BKRS | D4: T2 | E4: 1 | F4: PERLIS | G4: 1 | H4: TNB T | I4: 1 | J4: 21.207 | K4: 0.2278
A5: 51089 | B5: CBJC132 132.00 | C5: =LEFT(B5,4) -> CBJC | D5: T1 | E5: 1 | F5: PERLIS | G5: 1 | H5: TNB T | I5: 1 | J5: 27.6561 | K5: -1.8784
A6: 96176 | B6: CMBG132 132.00 | C6: =LEFT(B6,4) -> CMBG | D6: T3 | E6: 1 | F6: PERLIS | G6: 1 | H6: TNB T | I6: 1 | J6: 18.4629 | K6: 1.8432
A7: 61101 | B7: CPNG132 132.00 | C7: =LEFT(B7,4) -> CPNG | D7: T1 | E7: 1 | F7: PERLIS | G7: 1 | H7: TNB T | I7: 1 | J7: 5.7418 | K7: 0.5561
A8: 61101 | B8: CPNG132 132.00 | C8: =LEFT(B8,4) -> CPNG | D8: T2 | E8: 1 | F8: PERLIS | G8: 1 | H8: TNB T | I8: 1 | J8: 5.7594 | K8: 0.5612
A9: 61137 | B9: KGAR132 132.00 | C9: =LEFT(B9,4) -> KGAR | D9: T1 | E9: 1 | F9: PERLIS | G9: 1 | H9: TNB T | I9: 1 | J9: 12.0377 | K9: 3.4565
A10: 61137 | B10: KGAR132 132.00 | C10: =LEFT(B10,4) -> KGAR | D10: T2 | E10: 1 | F10: PERLIS | G10: 1 | H10: TNB T | I10: 1 | J10: 11.7281 | K10: 0.1325
A11: 61137 | B11: KGAR132 132.00 | C11: =LEFT(B11,4) -> KGAR | D11: T3 | E11: 1 | F11: PERLIS | G11: 1 | H11: TNB T | I11: 1 | J11: 7.408 | K11: 0.1905
A12: 61137 | B12: KGAR132 132.00 | C12: =LEFT(B12,4) -> KGAR | D12: T4 | E12: 1 | F12: PERLIS | G12: 1 | H12: TNB T | I12: 1 | J12: 10.9504 | K12: 0.3707
A13: 61102 | B13: KPLS132 132.00 | C13: =LEFT(B13,4) -> KPLS | D13: T1 | E13: 1 | F13: PERLIS | G13: 1 | H13: TNB T | I13: 1 | J13: 9.0347 | K13: 1.1577
... A903: 97177 | B903: PBJB132 132.00 | C903: =LEFT(B903,4) -> PBJB | D903: T4 | E903: 9 | F903: JOHOR | G903: 1 | H903: TNB T | I903: 1 | J903: 43.2466 | K903: 3.6408
A904: 97244 | B904: PCGP275 275.00 | C904: =LEFT(B904,4) -> PCGP | D904: 1 | E904: 9 | F904: JOHOR | G904: 1 | H904: TNB T | I904: 1 | J904: 0 | K904: 0
A905: 97153 | B905: PGDT132 132.00 | C905: =LEFT(B905,4) -> PGDT | D905: T1 | E905: 9 | F905: JOHOR | G905: 1 | H905: TNB T | I905: 1 | J905: 2.4873 | K905: 0.0269
A906: 97153 | B906: PGDT132 132.00 | C906: =LEFT(B906,4) -> PGDT | D906: T2 | E906: 9 | F906: JOHOR | G906: 1 | H906: TNB T | I906: 1 | J906: 10.1427 | K906: 2.4842
A907: 97153 | B907: PGDT132 132.00 | C907: =LEFT(B907,4) -> PGDT | D907: T3 | E907: 9 | F907: JOHOR | G907: 40 | H907: CAPACITORS | I907: 1 | J907: 16.3681 | K907: 4.4123
A908: 97153 | B908: PGDT132 132.00 | C908: =LEFT(B908,4) -> PGDT | D908: T4 | E908: 9 | F908: JOHOR | G908: 40 | H908: CAPACITORS | I908: 1 | J908: 16.4624 | K908: 4.4516
A909: 97191 | B909: PGEH132 132.00 | C909: =LEFT(B909,4) -> PGEH | D909: T1 | E909: 9 | F909: JOHOR | G909: 1 | H909: TNB T | I909: 1 | J909: 2.0379 | K909: -0.378
A910: 97191 | B910: PGEH132 132.00 | C910: =LEFT(B910,4) -> PGEH | D910: T2 | E910: 9 | F910: JOHOR | G910: 1 | H910: TNB T | I910: 1 | J910: 2.0275 | K910: -0.3676
A911: 97123 | B911: PGIE132 132.00 | C911: =LEFT(B911,4) -> PGIE | D911: T1 | E911: 9 | F911: JOHOR | G911: 1 | H911: TNB T | I911: 1 | J911: 13.8622 | K911: 1.9882
A912: 97123 | B912: PGIE132 132.00 | C912: =LEFT(B912,4) -> PGIE | D912: T2 | E912: 9 | F912: JOHOR | G912: 1 | H912: TNB T | I912: 1 | J912: 13.8715 | K912: 1.9861
A913: 97123 | B913: PGIE132 132.00 | C913: =LEFT(B913,4) -> PGIE | D913: T3 | E913: 9 | F913: JOHOR | G913: 1 | H913: TNB T | I913: 1 | J913: 12.4343 | K913: 1.3068
A914: 97179 | B914: PGOH132 132.00 | C914: =LEFT(B914,4) -> PGOH | D914: T1 | E914: 9 | F914: JOHOR | G914: 1 | H914: TNB T | I914: 1 | J914: 3.4762 | K914: -0.5033
A915: 97179 | B915: PGOH132 132.00 | C915: =LEFT(B915,4) -> PGOH | D915: T2 | E915: 9 | F915: JOHOR | G915: 1 | H915: TNB T | I915: 1 | J915: 3.4658 | K915: -0.5136
A916: 97114 | B916: PGPS132 132.00 | C916: =LEFT(B916,4) -> PGPS | D916: N1 | E916: 9 | F916: JOHOR | G916: 1 | H916: TNB T | I916: 1 | J916: 0 | K916: 0
... A1068: 74101 | B1068: BTRT132 132.00 | C1068: =LEFT(B1068,4) -> BTRT | D1068: T2 | E1068: 10 | F1068: PAHANG | G1068: 1 | H1068: TNB T | I1068: 1 | J1068: 0.5478 | K1068: -0.1854
A1069: 74150 | B1069: CUFG132 132.00 | C1069: =LEFT(B1069,4) -> CUFG | D1069: 99 | E1069: 10 | F1069: PAHANG | G1069: 1 | H1069: TNB T | I1069: 1 | J1069: 0 | K1069: 0
A1070: 74137 | B1070: GBID132 132.00 | C1070: =LEFT(B1070,4) -> GBID | D1070: T1 | E1070: 10 | F1070: PAHANG | G1070: 1 | H1070: TNB T | I1070: 1 | J1070: 22.3958 | K1070: -0.3438
A1071: 74137 | B1071: GBID132 132.00 | C1071: =LEFT(B1071,4) -> GBID | D1071: T2 | E1071: 10 | F1071: PAHANG | G1071: 1 | H1071: TNB T | I1071: 1 | J1071: 0 | K1071: 0
A1072: 74138 | B1072: GBNG132 132.00 | C1072: =LEFT(B1072,4) -> GBNG | D1072: T1 | E1072: 10 | F1072: PAHANG | G1072: 1 | H1072: TNB T | I1072: 1 | J1072: 2.7917 | K1072: 0.5478
A1073: 74138 | B1073: GBNG132 132.00 | C1073: =LEFT(B1073,4) -> GBNG | D1073: T2 | E1073: 10 | F1073: PAHANG | G1073: 1 | H1073: TNB T | I1073: 1 | J1073: 7.7517 | K1073: 1.3089
A1074: 74138 | B1074: GBNG132 132.00 | C1074: =LEFT(B1074,4) -> GBNG | D1074: T3 | E1074: 10 | F1074: PAHANG | G1074: 40 | H1074: CAPACITORS | I1074: 1 | J1074: 12.6144 | K1074: 0.7062
A1075: 74138 | B1075: GBNG132 132.00 | C1075: =LEFT(B1075,4) -> GBNG | D1075: T4 | E1075: 10 | F1075: PAHANG | G1075: 40 | H1075: CAPACITORS | I1075: 1 | J1075: 12.4167 | K1075: 0.6959
A1076: 74125 | B1076: GTNG132 132.00 | C1076: =LEFT(B1076,4) -> GTNG | D1076: T1 | E1076: 10 | F1076: PAHANG | G1076: 1 | H1076: TNB T | I1076: 1 | J1076: 1.0024 | K1076: -0.0228
A1077: 74125 | B1077: GTNG132 132.00 | C1077: =LEFT(B1077,4) -> GTNG | D1077: T2 | E1077: 10 | F1077: PAHANG | G1077: 1 | H1077: TNB T | I1077: 1 | J1077: 5.9552 | K1077: 0.4256
A1078: 74135 | B1078: JBRS132 132.00 | C1078: =LEFT(B1078,4) -> JBRS | D1078: T1 | E1078: 10 | F1078: PAHANG | G1078: 1 | H1078: TNB T | I1078: 1 | J1078: 9.0151 | K1078: -0.8243
A1079: 74135 | B1079: JBRS132 132.00 | C1079: =LEFT(B1079,4) -> JBRS | D1079: T2 | E1079: 10 | F1079: PAHANG | G1079: 1 | H1079: TNB T | I1079: 1 | J1079: 7.8035 | K1079: -1.3907
A1080: 74135 | B1080: JBRS132 132.00 | C1080: =LEFT(B1080,4) -> JBRS | D1080: T3 | E1080: 10 | F1080: PAHANG | G1080: 1 | H1080: TNB T | I1080: 1 | J1080: 4.1958 | K1080: -0.9837
...

Sheet UFLS 2024
B1: UFLS2024
B3: Bus Number | C3: Id | D3: Hz | E3: Substation | F3: Zone | G3: Load (PSSE)
B4: 97178 | C4: T2 | D4: 49.2 | E4: CBRU132 | F4: JOHOR | G4: 8.9519
B5: 97178 | C5: T1 | D5: 49.2 | E5: CBRU132 | F5: JOHOR | G5: 8.9871
B6: 97153 | C6: T2 | D6: 49.2 | E6: PGDT132 | F6: JOHOR | G6: 10.1427
B7: 97153 | C7: T1 | D7: 49.2 | E7: PGDT132 | F7: JOHOR | G7: 2.4873
B8: 97192 | C8: T2 | D8: 49.2 | E8: TMPI132 | F8: JOHOR | G8: 27.9139
B9: 97192 | C9: T1 | D9: 49.2 | E9: TMPI132 | F9: JOHOR | G9: 29.0913
B10: 62128 | C10: T2 | D10: 49.2 | E10: SARA132 | F10: P PINANG | G10: 35.7174
B11: 62128 | C11: T1 | D11: 49.2 | E11: SARA132 | F11: P PINANG | G11: 35.6077
B12: 74115 | C12: T2 | D12: 49.2 | E12: PKNI132 | F12: PAHANG | G12: 6.3124
B13: 74115 | C13: T1 | D13: 49.2 | E13: PKNI132 | F13: PAHANG | G13: 6.2824
B14: 96106 | C14: T2 | D14: 49.2 | E14: HPGH132 | F14: MELAKA | G14: 6.0111
B15: 96106 | C15: T1 | D15: 49.2 | E15: HPGH132 | F15: MELAKA | G15: 5.9893
... B141: 74106 | C141: T3 | D141: 48.9 | E141: TGLN132 | F141: PAHANG | G141: 11.2642
B142: #N/A | C142: T2 | D142: 48.8 | E142: KSTR132 | F142: #N/A | G142: #N/A
B143: #N/A | C143: T1 | D143: 48.8 | E143: KSTR132 | F143: #N/A | G143: #N/A
B144: 51031 | C144: T2 | D144: 48.8 | E144: KCPK132 | F144: SELANGOR | G144: 31.0246
B145: 51031 | C145: T1 | D145: 48.8 | E145: KCPK132 | F145: SELANGOR | G145: 31.1292
B146: 51200 | C146: T2 | D146: 48.8 | E146: NRWG132 | F146: SELANGOR | G146: 37.5762
B147: 51200 | C147: T1 | D147: 48.8 | E147: NRWG132 | F147: SELANGOR | G147: 37.6476
B148: 51045 | C148: T4 | D148: 48.8 | E148: BKPR132 | F148: SELANGOR | G148: 38.7432
B149: 51045 | C149: T3 | D149: 48.8 | E149: BKPR132 | F149: SELANGOR | G149: 38.7349
B150: 51084 | C150: T2 | D150: 48.8 | E150: TMSY132 | F150: SELANGOR | G150: 15.4766
B151: 51084 | C151: T1 | D151: 48.8 | E151: TMSY132 | F151: SELANGOR | G151: 15.5138
B152: 96144 | C152: T2 | D152: 48.8 | E152: TKMG132 | F152: NS | G152: 6.827
B153: 96144 | C153: T1 | D153: 48.8 | E153: TKMG132 | F153: NS | G153: 6.8529
B154: 96147 | C154: T2 | D154: 48.8 | E154: PPJG132 | F154: MELAKA | G154: 10.589
B155: 96147 | C155: T1 | D155: 48.8 | E155: PPJG132 | F155: MELAKA | G155: 0
... B157: 96173 | C157: T5 | D157: 48.8 | E157: MTNH132 | F157: MELAKA | G157: 11.3801
B158: #N/A | C158: T4 | D158: 48.8 | E158: MTNH132 | F158: #N/A | G158: #N/A
B159: 96173 | C159: T3 | D159: 48.8 | E159: MTNH132 | F159: MELAKA | G159: 2.8093
B160: 96173 | C160: T2 | D160: 48.8 | E160: MTNH132 | F160: MELAKA | G160: 6.2451
B161: 96173 | C161: T1 | D161: 48.8 | E161: MTNH132 | F161: MELAKA | G161: 6.2285
B162: 96135 | C162: T4 | D162: 48.8 | E162: TJID132 | F162: NS | G162: 19.9893
B163: 96135 | C163: T3 | D163: 48.8 | E163: TJID132 | F163: NS | G163: 19.9675
B164: 96135 | C164: T2 | D164: 48.8 | E164: TJID132 | F164: NS | G164: 7.8615
B165: 96135 | C165: T1 | D165: 48.8 | E165: TJID132 | F165: NS | G165: 11.1275
B166: 96129 | C166: T2 | D166: 48.8 | E166: TTJF132 | F166: NS | G166: 14.9029
B167: 96129 | C167: T1 | D167: 48.8 | E167: TTJF132 | F167: NS | G167: 14.8677
...

Sheet Working tab (ref)
A2: Assigned Feeders | B2: CB | C2: MW Quantum 2024 | D2: MW Quantum 2025 | E2: Load Area Affected | H2: UFLS DYR | O2: Load (PSSE) | R2: PSSE | Z2: PSSE (reference)
A3: 132/22kV T1 & T2 | B3: 1T0 & 2T0 | C3: 21.3659 | E3: CBRU 22kV | H3: =VLOOKUP(AH3,$AD$3:$AF$1300,3,FALSE) -> 97178 | I3: T2 | J3: 49.2 | K3: CBRU132 | M3: =K3&I3 -> CBRU132T2 | N3: =VLOOKUP(H3,'TNB Load'!$A$2:$F$1448,6,FALSE) -> JOHOR | O3: =VLOOKUP(M3,$W$3:$X$1300,2,FALSE) -> 8.9519 | R3: 63177 | S3: AYTH132 132.00 | T3: T7 | U3: =LEFT(S3,7) -> AYTH132 | W3: =U3&T3 -> AYTH132T7 | X3: 11.6897 | Z3: AYTH132 132.00 | AA3: T7 | AB3: AYTH132 | AD3: AYTH132T7 | AE3: 11.6897 | AF3: 63177 | AH3: CBRU132T2
A4: 132/22kV T1 & T2 | B4: 1T0 & 2T0 | C4: 21.8789 | E4: PGDT 22kV | H4: =VLOOKUP(AH4,$AD$3:$AF$1300,3,FALSE) -> 97178 | I4: T1 | J4: 49.2 | K4: CBRU132 | M4: =K4&I4 -> CBRU132T1 | N4: =VLOOKUP(H4,'TNB Load'!$A$2:$F$1448,6,FALSE) -> JOHOR | O4: =VLOOKUP(M4,$W$3:$X$1300,2,FALSE) -> 8.9871 | R4: 61123 | S4: BKRS132 132.00 | T4: T1 | U4: =LEFT(S4,7) -> BKRS132 | W4: =U4&T4 -> BKRS132T1 | X4: 21.2899 | Z4: BKRS132 132.00 | AA4: T1 | AB4: BKRS132 | AD4: BKRS132T1 | AE4: 21.2899 | AF4: 61123 | AH4: CBRU132T1
A5: 132/33kV T1 & T2 | B5: 1T0 & 2T0 | C5: 64.0768 | E5: TMPI 33kV | H5: =VLOOKUP(AH5,$AD$3:$AF$1300,3,FALSE) -> 97153 | I5: T2 | J5: 49.2 | K5: PGDT132 | M5: =K5&I5 -> PGDT132T2 | N5: =VLOOKUP(H5,'TNB Load'!$A$2:$F$1448,6,FALSE) -> JOHOR | O5: =VLOOKUP(M5,$W$3:$X$1300,2,FALSE) -> 10.1427 | R5: 61123 | S5: BKRS132 132.00 | T5: T2 | U5: =LEFT(S5,7) -> BKRS132 | W5: =U5&T5 -> BKRS132T2 | X5: 21.207 | Z5: BKRS132 132.00 | AA5: T2 | AB5: BKRS132 | AD5: BKRS132T2 | AE5: 21.207 | AF5: 61123 | AH5: PGDT132T2
A6: 132/33kV T1 & T2 | B6: 1T0 & 2T0 | C6: 41.5461 | E6: SARA 33kV | H6: =VLOOKUP(AH6,$AD$3:$AF$1300,3,FALSE) -> 97153 | I6: T1 | J6: 49.2 | K6: PGDT132 | M6: =K6&I6 -> PGDT132T1 | N6: =VLOOKUP(H6,'TNB Load'!$A$2:$F$1448,6,FALSE) -> JOHOR | O6: =VLOOKUP(M6,$W$3:$X$1300,2,FALSE) -> 2.4873 | R6: 51089 | S6: CBJC132 132.00 | T6: T1 | U6: =LEFT(S6,7) -> CBJC132 | W6: =U6&T6 -> CBJC132T1 | X6: 27.6561 | Z6: CBJC132 132.00 | AA6: T1 | AB6: CBJC132 | AD6: CBJC132T1 | AE6: 27.6561 | AF6: 51089 | AH6: PGDT132T1
A7: 132/33kV T1 & T2 | B7: 1T0 & 2T1 | C7: 18.5562 | E7: PKNI 33kV | H7: =VLOOKUP(AH7,$AD$3:$AF$1300,3,FALSE) -> 97192 | I7: T2 | J7: 49.2 | K7: TMPI132 | M7: =K7&I7 -> TMPI132T2 | N7: =VLOOKUP(H7,'TNB Load'!$A$2:$F$1448,6,FALSE) -> JOHOR | O7: =VLOOKUP(M7,$W$3:$X$1300,2,FALSE) -> 27.9139 | R7: 96176 | S7: CMBG132 132.00 | T7: T3 | U7: =LEFT(S7,7) -> CMBG132 | W7: =U7&T7 -> CMBG132T3 | X7: 18.4629 | Z7: CMBG132 132.00 | AA7: T3 | AB7: CMBG132 | AD7: CMBG132T3 | AE7: 18.4629 | AF7: 96176 | AH7: TMPI132T2
A8: 132/33kV T1 & T2 | B8: 1T0 & 2T0 | C8: 15.3861 | E8: HPGH 33kV | H8: =VLOOKUP(AH8,$AD$3:$AF$1300,3,FALSE) -> 97192 | I8: T1 | J8: 49.2 | K8: TMPI132 | M8: =K8&I8 -> TMPI132T1 | N8: =VLOOKUP(H8,'TNB Load'!$A$2:$F$1448,6,FALSE) -> JOHOR | O8: =VLOOKUP(M8,$W$3:$X$1300,2,FALSE) -> 29.0913 | R8: 61101 | S8: CPNG132 132.00 | T8: T1 | U8: =LEFT(S8,7) -> CPNG132 | W8: =U8&T8 -> CPNG132T1 | X8: 5.7418 | Z8: CPNG132 132.00 | AA8: T1 | AB8: CPNG132 | AD8: CPNG132T1 | AE8: 5.7418 | AF8: 61101 | AH8: TMPI132T1
A9: 132/33kV T1 & T2 | B9: 1T0 & 2T0 | C9: 36.4197 | E9: ESTK 33kV | H9: =VLOOKUP(AH9,$AD$3:$AF$1300,3,FALSE) -> 62128 | I9: T2 | J9: 49.2 | K9: SARA132 | M9: =K9&I9 -> SARA132T2 | N9: =VLOOKUP(H9,'TNB Load'!$A$2:$F$1448,6,FALSE) -> P PINANG | O9: =VLOOKUP(M9,$W$3:$X$1300,2,FALSE) -> 35.7174 | R9: 61101 | S9: CPNG132 132.00 | T9: T2 | U9: =LEFT(S9,7) -> CPNG132 | W9: =U9&T9 -> CPNG132T2 | X9: 5.7594 | Z9: CPNG132 132.00 | AA9: T2 | AB9: CPNG132 | AD9: CPNG132T2 | AE9: 5.7594 | AF9: 61101 | AH9: SARA132T2
A10: 132/11kV T1 & T2 | B10: 30 & 32 | C10: 20.2233 | E10: KRPH 11kV | H10: =VLOOKUP(AH10,$AD$3:$AF$1300,3,FALSE) -> 62128 | I10: T1 | J10: 49.2 | K10: SARA132 | M10: =K10&I10 -> SARA132T1 | N10: =VLOOKUP(H10,'TNB Load'!$A$2:$F$1448,6,FALSE) -> P PINANG | O10: =VLOOKUP(M10,$W$3:$X$1300,2,FALSE) -> 35.6077 | R10: 61137 | S10: KGAR132 132.00 | T10: T1 | U10: =LEFT(S10,7) -> KGAR132 | W10: =U10&T10 -> KGAR132T1 | X10: 12.0377 | Z10: KGAR132 132.00 | AA10: T1 | AB10: KGAR132 | AD10: KGAR132T1 | AE10: 12.0377 | AF10: 61137 | AH10: SARA132T1
A11: 132/11kV T1 & T2 | B11: 31 & 32 | C11: 21.5372 | E11: PKID 11kV | H11: =VLOOKUP(AH11,$AD$3:$AF$1300,3,FALSE) -> 74115 | I11: T2 | J11: 49.2 | K11: PKNI132 | M11: =K11&I11 -> PKNI132T2 | N11: =VLOOKUP(H11,'TNB Load'!$A$2:$F$1448,6,FALSE) -> PAHANG | O11: =VLOOKUP(M11,$W$3:$X$1300,2,FALSE) -> 6.3124 | R11: 61137 | S11: KGAR132 132.00 | T11: T2 | U11: =LEFT(S11,7) -> KGAR132 | W11: =U11&T11 -> KGAR132T2 | X11: 11.7281 | Z11: KGAR132 132.00 | AA11: T2 | AB11: KGAR132 | AD11: KGAR132T2 | AE11: 11.7281 | AF11: 61137 | AH11: PKNI132T2
A12: 132/33kV T3 & T4 | B12: 3T0 & 4T0 | C12: 25.2821 | E12: PKID 33kV | H12: =VLOOKUP(AH12,$AD$3:$AF$1300,3,FALSE) -> 74115 | I12: T1 | J12: 49.2 | K12: PKNI132 | M12: =K12&I12 -> PKNI132T1 | N12: =VLOOKUP(H12,'TNB Load'!$A$2:$F$1448,6,FALSE) -> PAHANG | O12: =VLOOKUP(M12,$W$3:$X$1300,2,FALSE) -> 6.2824 | R12: 61137 | S12: KGAR132 132.00 | T12: T3 | U12: =LEFT(S12,7) -> KGAR132 | W12: =U12&T12 -> KGAR132T3 | X12: 7.408 | Z12: KGAR132 132.00 | AA12: T3 | AB12: KGAR132 | AD12: KGAR132T3 | AE12: 7.408 | AF12: 61137 | AH12: PKNI132T1
A13: 132/33kV T3 & T4 | B13: 3T0, 4T0 & 1W0 | C13: 61.5771 | E13: KVRT 33 kV | H13: =VLOOKUP(AH13,$AD$3:$AF$1300,3,FALSE) -> 96106 | I13: T2 | J13: 49.2 | K13: HPGH132 | M13: =K13&I13 -> HPGH132T2 | N13: =VLOOKUP(H13,'TNB Load'!$A$2:$F$1448,6,FALSE) -> MELAKA | O13: =VLOOKUP(M13,$W$3:$X$1300,2,FALSE) -> 6.0111 | R13: 61137 | S13: KGAR132 132.00 | T13: T4 | U13: =LEFT(S13,7) -> KGAR132 | W13: =U13&T13 -> KGAR132T4 | X13: 10.9504 | Z13: KGAR132 132.00 | AA13: T4 | AB13: KGAR132 | AD13: KGAR132T4 | AE13: 10.9504 | AF13: 61137 | AH13: HPGH132T2
A14: 132/33kV T3 & T4 | B14: 3T0 & 4T0 | C14: 83.9211 | E14: MLBU 33kV | H14: =VLOOKUP(AH14,$AD$3:$AF$1300,3,FALSE) -> 96106 | I14: T1 | J14: 49.2 | K14: HPGH132 | M14: =K14&I14 -> HPGH132T1 | N14: =VLOOKUP(H14,'TNB Load'!$A$2:$F$1448,6,FALSE) -> MELAKA | O14: =VLOOKUP(M14,$W$3:$X$1300,2,FALSE) -> 5.9893 | R14: 61102 | S14: KPLS132 132.00 | T14: T1 | U14: =LEFT(S14,7) -> KPLS132 | W14: =U14&T14 -> KPLS132T1 | X14: 9.0347 | Z14: KPLS132 132.00 | AA14: T1 | AB14: KPLS132 | AD14: KPLS132T1 | AE14: 9.0347 | AF14: 61102 | AH14: HPGH132T1
... A29: 132/11kV T1 & T2 | B29: 31 & 32 | C29: 24.5161 | E29: NUNI 11kV | H29: =VLOOKUP(AH29,$AD$3:$AF$1300,3,FALSE) -> 88128 | I29: T2 | J29: 49.2 | K29: MJLR132 | M29: =K29&I29 -> MJLR132T2 | N29: =VLOOKUP(H29,'TNB Load'!$A$2:$F$1448,6,FALSE) -> WPKL | O29: =VLOOKUP(M29,$W$3:$X$1300,2,FALSE) -> 49.3467 | R29: 61124 | S29: BKHM132 132.00 | T29: T2 | U29: =LEFT(S29,7) -> BKHM132 | W29: =U29&T29 -> BKHM132T2 | X29: 6.0483 | Z29: BKHM132 132.00 | AA29: T2 | AB29: BKHM132 | AD29: BKHM132T2 | AE29: 6.0483 | AF29: 61124 | AH29: MJLR132T2
A30: WA18 1 & 2 | B30: H10 & H20 | C30: - | E30: TNB-Singapore Interconnection | H30: =VLOOKUP(AH30,$AD$3:$AF$1300,3,FALSE) -> 88128 | I30: T1 | J30: 49.2 | K30: MJLR132 | M30: =K30&I30 -> MJLR132T1 | N30: =VLOOKUP(H30,'TNB Load'!$A$2:$F$1448,6,FALSE) -> WPKL | O30: =VLOOKUP(M30,$W$3:$X$1300,2,FALSE) -> 49.94 | R30: 61124 | S30: BKHM132 132.00 | T30: T3 | U30: =LEFT(S30,7) -> BKHM132 | W30: =U30&T30 -> BKHM132T3 | X30: 18.2548 | Z30: BKHM132 132.00 | AA30: T3 | AB30: BKHM132 | AD30: BKHM132T3 | AE30: 18.2548 | AF30: 61124 | AH30: MJLR132T1
A31: 132/22kV T1 & T2 | B31: 1T0 & 2T0 | C31: 29.3428 | E31: TBRU 22kV | H31: =VLOOKUP(AH31,$AD$3:$AF$1300,3,FALSE) -> 88142 | I31: T2 | J31: 49.2 | K31: SHMS132 | M31: =K31&I31 -> SHMS132T2 | N31: =VLOOKUP(H31,'TNB Load'!$A$2:$F$1448,6,FALSE) -> WPKL | O31: =VLOOKUP(M31,$W$3:$X$1300,2,FALSE) -> 28.1138 | R31: 61124 | S31: BKHM132 132.00 | T31: T4 | U31: =LEFT(S31,7) -> BKHM132 | W31: =U31&T31 -> BKHM132T4 | X31: 18.319 | Z31: BKHM132 132.00 | AA31: T4 | AB31: BKHM132 | AD31: BKHM132T4 | AE31: 18.319 | AF31: 61124 | AH31: SHMS132T2
A32: KRYG 1 & 2 | B32: 305 & 405 | C32: 30 | E32: KRYG | H32: =VLOOKUP(AH32,$AD$3:$AF$1300,3,FALSE) -> 88142 | I32: T1 | J32: 49.2 | K32: SHMS132 | M32: =K32&I32 -> SHMS132T1 | N32: =VLOOKUP(H32,'TNB Load'!$A$2:$F$1448,6,FALSE) -> WPKL | O32: =VLOOKUP(M32,$W$3:$X$1300,2,FALSE) -> 28.2235 | R32: 61120 | S32: BSBU132 132.00 | T32: T1 | U32: =LEFT(S32,7) -> BSBU132 | W32: =U32&T32 -> BSBU132T1 | X32: 6.1395 | Z32: BSBU132 132.00 | AA32: T1 | AB32: BSBU132 | AD32: BSBU132T1 | AE32: 6.1395 | AF32: 61120 | AH32: SHMS132T1
A33: SHEL 1 & 2 | B33: 505 & 605 | C33: 36 | E33: SHELL | H33: =VLOOKUP(AH33,$AD$3:$AF$1300,3,FALSE) -> 88107 | I33: T2 | J33: 49.2 | K33: SCTY132 | M33: =K33&I33 -> SCTY132T2 | N33: =VLOOKUP(H33,'TNB Load'!$A$2:$F$1448,6,FALSE) -> WPKL | O33: =VLOOKUP(M33,$W$3:$X$1300,2,FALSE) -> 17.0774 | R33: 61120 | S33: BSBU132 132.00 | T33: T2 | U33: =LEFT(S33,7) -> BSBU132 | W33: =U33&T33 -> BSBU132T2 | X33: 6.1125 | Z33: BSBU132 132.00 | AA33: T2 | AB33: BSBU132 | AD33: BSBU132T2 | AE33: 6.1125 | AF33: 61120 | AH33: SCTY132T2
A34: 132/33kV T1 & T2 | B34: 1T0 & 2T0 | C34: 77.918 | E34: HCOM 33 kV | H34: =VLOOKUP(AH34,$AD$3:$AF$1300,3,FALSE) -> 88107 | I34: T1 | J34: 49.2 | K34: SCTY132 | M34: =K34&I34 -> SCTY132T1 | N34: =VLOOKUP(H34,'TNB Load'!$A$2:$F$1448,6,FALSE) -> WPKL | O34: =VLOOKUP(M34,$W$3:$X$1300,2,FALSE) -> 17.1303 | R34: 61120 | S34: BSBU132 132.00 | T34: T3 | U34: =LEFT(S34,7) -> BSBU132 | W34: =U34&T34 -> BSBU132T3 | X34: 0 | Z34: BSBU132 132.00 | AA34: T3 | AB34: BSBU132 | AD34: BSBU132T3 | AE34: 0 | AF34: 61120 | AH34: SCTY132T1
A35: 132/33kV T3 & T4 & T5 | B35: 3T0 & 4T0 & 5T0 | C35: 72.8698 | E35: SHAE 33kV | H35: =VLOOKUP(AH35,$AD$3:$AF$1300,3,FALSE) -> 51038 | I35: T3 | J35: 49.2 | K35: CJYA132 | M35: =K35&I35 -> CJYA132T3 | N35: =VLOOKUP(H35,'TNB Load'!$A$2:$F$1448,6,FALSE) -> SELANGOR | O35: =VLOOKUP(M35,$W$3:$X$1300,2,FALSE) -> 66.9274 | R35: 61120 | S35: BSBU132 132.00 | T35: T4 | U35: =LEFT(S35,7) -> BSBU132 | W35: =U35&T35 -> BSBU132T4 | X35: 0 | Z35: BSBU132 132.00 | AA35: T4 | AB35: BSBU132 | AD35: BSBU132T4 | AE35: 0 | AF35: 61120 | AH35: CJYA132T3
A36: 132/33kV T1 & T2 | B36: 1T0 & 2T0 | C36: 64 | E36: SHAS 33kV | H36: =VLOOKUP(AH36,$AD$3:$AF$1300,3,FALSE) -> 51038 | I36: T2 | J36: 49.2 | K36: CJYA132 | M36: =K36&I36 -> CJYA132T2 | N36: =VLOOKUP(H36,'TNB Load'!$A$2:$F$1448,6,FALSE) -> SELANGOR | O36: =VLOOKUP(M36,$W$3:$X$1300,2,FALSE) -> 33.5056 | R36: 61108 | S36: GCPD132 132.00 | T36: T1 | U36: =LEFT(S36,7) -> GCPD132 | W36: =U36&T36 -> GCPD132T1 | X36: 6.242 | Z36: GCPD132 132.00 | AA36: T1 | AB36: GCPD132 | AD36: GCPD132T1 | AE36: 6.242 | AF36: 61108 | AH36: CJYA132T2
A37: 132/33kV T2 & T3 & T4 | B37: 2T0, 3T0 & 4T0 | C37: 67.9031 | E37: PCOR 33kV | H37: =VLOOKUP(AH37,$AD$3:$AF$1300,3,FALSE) -> 51038 | I37: T1 | J37: 49.2 | K37: CJYA132 | M37: =K37&I37 -> CJYA132T1 | N37: =VLOOKUP(H37,'TNB Load'!$A$2:$F$1448,6,FALSE) -> SELANGOR | O37: =VLOOKUP(M37,$W$3:$X$1300,2,FALSE) -> 31.8343 | R37: 61108 | S37: GCPD132 132.00 | T37: T2 | U37: =LEFT(S37,7) -> GCPD132 | W37: =U37&T37 -> GCPD132T2 | X37: 6.2492 | Z37: GCPD132 132.00 | AA37: T2 | AB37: GCPD132 | AD37: GCPD132T2 | AE37: 6.2492 | AF37: 61108 | AH37: CJYA132T1
A38: 132/11kV T1 & T2 | B38: 31 & 32 | C38: 20.2863 | E38: JTGH 11kV | H38: =VLOOKUP(AH38,$AD$3:$AF$1300,3,FALSE) -> 88195 | I38: T4 | J38: 49.2 | K38: DDSA132 | M38: =K38&I38 -> DDSA132T4 | N38: =VLOOKUP(H38,'TNB Load'!$A$2:$F$1448,6,FALSE) -> WPKL | O38: =VLOOKUP(M38,$W$3:$X$1300,2,FALSE) -> 30.6943 | R38: 61116 | S38: GRNE132 132.00 | T38: T1 | U38: =LEFT(S38,7) -> GRNE132 | W38: =U38&T38 -> GRNE132T1 | X38: 16.9304 | Z38: GRNE132 132.00 | AA38: T1 | AB38: GRNE132 | AD38: GRNE132T1 | AE38: 16.9304 | AF38: 61116 | AH38: DDSA132T4
A39: 132/33kV T1 & T2 | B39: 1T0 & 2T0 | C39: 74.3213 | E39: SJAY 33kV | H39: =VLOOKUP(AH39,$AD$3:$AF$1300,3,FALSE) -> 88195 | I39: T3 | J39: 49.2 | K39: DDSA132 | M39: =K39&I39 -> DDSA132T3 | N39: =VLOOKUP(H39,'TNB Load'!$A$2:$F$1448,6,FALSE) -> WPKL | O39: =VLOOKUP(M39,$W$3:$X$1300,2,FALSE) -> 30.6777 | R39: 61116 | S39: GRNE132 132.00 | T39: T2 | U39: =LEFT(S39,7) -> GRNE132 | W39: =U39&T39 -> GRNE132T2 | X39: 16.9325 | Z39: GRNE132 132.00 | AA39: T2 | AB39: GRNE132 | AD39: GRNE132T2 | AE39: 16.9325 | AF39: 61116 | AH39: DDSA132T3
A40: 132/33kV T3 & T4 | B40: 3T0&4T0 | C40: 51.9714 | E40: INTN 33kV | H40: =VLOOKUP(AH40,$AD$3:$AF$1300,3,FALSE) -> 61119 | I40: T2 | J40: 49.2 | K40: MGON132 | M40: =K40&I40 -> MGON132T2 | N40: =VLOOKUP(H40,'TNB Load'!$A$2:$F$1448,6,FALSE) -> KEDAH | O40: =VLOOKUP(M40,$W$3:$X$1300,2,FALSE) -> 8.2529 | R40: 61109 | S40: GRUN132 132.00 | T40: T1 | U40: =LEFT(S40,7) -> GRUN132 | W40: =U40&T40 -> GRUN132T1 | X40: 4.7177 | Z40: GRUN132 132.00 | AA40: T1 | AB40: GRUN132 | AD40: GRUN132T1 | AE40: 4.7177 | AF40: 61109 | AH40: MGON132T2
A41: 132/11kV T1 & T2 | B41: 31&32 | C41: 31.6547 | E41: INTN 22kV | H41: =VLOOKUP(AH41,$AD$3:$AF$1300,3,FALSE) -> 61119 | I41: T1 | J41: 49.2 | K41: MGON132 | M41: =K41&I41 -> MGON132T1 | N41: =VLOOKUP(H41,'TNB Load'!$A$2:$F$1448,6,FALSE) -> KEDAH | O41: =VLOOKUP(M41,$W$3:$X$1300,2,FALSE) -> 8.2591 | R41: 61109 | S41: GRUN132 132.00 | T41: T2 | U41: =LEFT(S41,7) -> GRUN132 | W41: =U41&T41 -> GRUN132T2 | X41: 4.6991 | Z41: GRUN132 132.00 | AA41: T2 | AB41: GRUN132 | AD41: GRUN132T2 | AE41: 4.6991 | AF41: 61109 | AH41: MGON132T1
A42: 132/11kV T1 & T2 | B42: 31 & 32 | C42: 9.404 | E42: MPSS 11kV | H42: =VLOOKUP(AH42,$AD$3:$AF$1300,3,FALSE) -> 61132 | I42: T2 | J42: 49.2 | K42: PAUH132 | M42: =K42&I42 -> PAUH132T2 | N42: =VLOOKUP(H42,'TNB Load'!$A$2:$F$1448,6,FALSE) -> KEDAH | O42: =VLOOKUP(M42,$W$3:$X$1300,2,FALSE) -> 18.9869 | R42: 61131 | S42: GTHR132 132.00 | T42: T1 | U42: =LEFT(S42,7) -> GTHR132 | W42: =U42&T42 -> GTHR132T1 | X42: 45.9937 | Z42: GTHR132 132.00 | AA42: T1 | AB42: GTHR132 | AD42: GTHR132T1 | AE42: 45.9937 | AF42: 61131 | AH42: PAUH132T2
... A51: 132/11kV T1 & T2 | B51: 31 & 32 | C51: 23.208 | E51: BNTG 11kV | H51: =VLOOKUP(AH51,$AD$3:$AF$1300,3,FALSE) -> 63134 | I51: T1 | J51: 49.1 | K51: TASK132 | M51: =K51&I51 -> TASK132T1 | N51: =VLOOKUP(H51,'TNB Load'!$A$2:$F$1448,6,FALSE) -> PERAK | O51: =VLOOKUP(M51,$W$3:$X$1300,2,FALSE) -> 4.8461 | R51: 61141 | S51: KERC132 132.00 | T51: T2 | U51: =LEFT(S51,7) -> KERC132 | W51: =U51&T51 -> KERC132T2 | X51: 0 | Z51: KERC132 132.00 | AA51: T2 | AB51: KERC132 | AD51: KERC132T2 | AE51: 0 | AF51: 61141 | AH51: TASK132T1
A52: 132/33 kV T1 & T2 | B52: 1T0 & 2T0 | E52: BWTN 33kV | H52: =VLOOKUP(AH52,$AD$3:$AF$1300,3,FALSE) -> 88162 | I52: T5 | J52: 49.1 | K52: SPKC132 | M52: =K52&I52 -> SPKC132T5 | N52: =VLOOKUP(H52,'TNB Load'!$A$2:$F$1448,6,FALSE) -> WPKL | O52: =VLOOKUP(M52,$W$3:$X$1300,2,FALSE) -> 55.7688 | R52: 61122 | S52: KKTL132 132.00 | T52: T1 | U52: =LEFT(S52,7) -> KKTL132 | W52: =U52&T52 -> KKTL132T1 | X52: 2.9998 | Z52: KKTL132 132.00 | AA52: T1 | AB52: KKTL132 | AD52: KKTL132T1 | AE52: 2.9998 | AF52: 61122 | AH52: SPKC132T5
A53: 132/11kV T5 | B53: 35 | E53: BWTN 11kV | H53: =VLOOKUP(AH53,$AD$3:$AF$1300,3,FALSE) -> 88162 | I53: T4 | J53: 49.1 | K53: SPKC132 | M53: =K53&I53 -> SPKC132T4 | N53: =VLOOKUP(H53,'TNB Load'!$A$2:$F$1448,6,FALSE) -> WPKL | O53: =VLOOKUP(M53,$W$3:$X$1300,2,FALSE) -> 49.4036 | R53: 61122 | S53: KKTL132 132.00 | T53: T2 | U53: =LEFT(S53,7) -> KKTL132 | W53: =U53&T53 -> KKTL132T2 | X53: 6.8405 | Z53: KKTL132 132.00 | AA53: T2 | AB53: KKTL132 | AD53: KKTL132T2 | AE53: 6.8405 | AF53: 61122 | AH53: SPKC132T4
A54: 132/33kV T3 & T4 | B54: 3T0 & 4T0 | C54: 61.6121 | E54: PRGS 33 kV | H54: =VLOOKUP(AH54,$AD$3:$AF$1300,3,FALSE) -> 88162 | I54: T3 | J54: 49.1 | K54: SPKC132 | M54: =K54&I54 -> SPKC132T3 | N54: =VLOOKUP(H54,'TNB Load'!$A$2:$F$1448,6,FALSE) -> WPKL | O54: =VLOOKUP(M54,$W$3:$X$1300,2,FALSE) -> 49.6522 | R54: 61122 | S54: KKTL132 132.00 | T54: T3 | U54: =LEFT(S54,7) -> KKTL132 | W54: =U54&T54 -> KKTL132T3 | X54: 20.566 | Z54: KKTL132 132.00 | AA54: T3 | AB54: KKTL132 | AD54: KKTL132T3 | AE54: 20.566 | AF54: 61122 | AH54: SPKC132T3
A55: 132/33kV T1 & T2 | B55: 1T0 & 2T0 | C55: 85.1885 | E55: SRDR 33kV | H55: =VLOOKUP(AH55,$AD$3:$AF$1300,3,FALSE) -> 51023 | I55: T2 | J55: 49.1 | K55: NUNI132 | M55: =K55&I55 -> NUNI132T2 | N55: =VLOOKUP(H55,'TNB Load'!$A$2:$F$1448,6,FALSE) -> SELANGOR | O55: =VLOOKUP(M55,$W$3:$X$1300,2,FALSE) -> 13.096 | R55: 61122 | S55: KKTL132 132.00 | T55: T4 | U55: =LEFT(S55,7) -> KKTL132 | W55: =U55&T55 -> KKTL132T4 | X55: 20.7876 | Z55: KKTL132 132.00 | AA55: T4 | AB55: KKTL132 | AD55: KKTL132T4 | AE55: 20.7876 | AF55: 61122 | AH55: NUNI132T2
A56: 132/33kV T3 & T4 | B56: 3T0 & 4T0 | C56: 75.8672 | E56: AMPG T3&T4 | H56: =VLOOKUP(AH56,$AD$3:$AF$1300,3,FALSE) -> 51023 | I56: T1 | J56: 49.1 | K56: NUNI132 | M56: =K56&I56 -> NUNI132T1 | N56: =VLOOKUP(H56,'TNB Load'!$A$2:$F$1448,6,FALSE) -> SELANGOR | O56: =VLOOKUP(M56,$W$3:$X$1300,2,FALSE) -> 12.719 | R56: 61113 | S56: KLIM132 132.00 | T56: T1 | U56: =LEFT(S56,7) -> KLIM132 | W56: =U56&T56 -> KLIM132T1 | X56: 34.6395 | Z56: KLIM132 132.00 | AA56: T1 | AB56: KLIM132 | AD56: KLIM132T1 | AE56: 34.6395 | AF56: 61113 | AH56: NUNI132T1
A57: 132/33kV T1 & T2 | B57: 1T0 & 2T0 | C57: 65.0735 | E57: AHTM 33kV | H57: =VLOOKUP(AH57,$AD$3:$AF$1300,3,FALSE) -> 97186 | I57: T2 | J57: 49.1 | K57: TBRU132 | M57: =K57&I57 -> TBRU132T2 | N57: =VLOOKUP(H57,'TNB Load'!$A$2:$F$1448,6,FALSE) -> JOHOR | O57: =VLOOKUP(M57,$W$3:$X$1300,2,FALSE) -> 0 | R57: 61113 | S57: KLIM132 132.00 | T57: T2 | U57: =LEFT(S57,7) -> KLIM132 | W57: =U57&T57 -> KLIM132T2 | X57: 34.8683 | Z57: KLIM132 132.00 | AA57: T2 | AB57: KLIM132 | AD57: KLIM132T2 | AE57: 34.8683 | AF57: 61113 | AH57: TBRU132T2
A58: 132/33kV T1 & T2 | B58: 1T0 & 2T0 | C58: 85.6804 | E58: BJLL 33kV | H58: =VLOOKUP(AH58,$AD$3:$AF$1300,3,FALSE) -> 97186 | I58: T1 | J58: 49.1 | K58: TBRU132 | M58: =K58&I58 -> TBRU132T1 | N58: =VLOOKUP(H58,'TNB Load'!$A$2:$F$1448,6,FALSE) -> JOHOR | O58: =VLOOKUP(M58,$W$3:$X$1300,2,FALSE) -> 23.2293 | R58: 61135 | S58: KSSM132 132.00 | T58: T1 | U58: =LEFT(S58,7) -> KSSM132 | W58: =U58&T58 -> KSSM132T1 | X58: 5.3318 | Z58: KSSM132 132.00 | AA58: T1 | AB58: KSSM132 | AD58: KSSM132T1 | AE58: 5.3318 | AF58: 61135 | AH58: TBRU132T1
A59: 132/33kV T3 & T4 | B59: 3T0 & 4T0 | C59: 52.1303 | E59: BLKG 33 kV | H59: =VLOOKUP(AH59,$AD$3:$AF$1300,3,FALSE) -> 74145 | I59: T2 | J59: 49.1 | K59: KRYG132 | M59: =K59&I59 -> KRYG132T2 | N59: =VLOOKUP(H59,'TNB Load'!$A$2:$F$1448,6,FALSE) -> PAHANG | O59: =VLOOKUP(M59,$W$3:$X$1300,2,FALSE) -> 0 | R59: 61135 | S59: KSSM132 132.00 | T59: T2 | U59: =LEFT(S59,7) -> KSSM132 | W59: =U59&T59 -> KSSM132T2 | X59: 5.3515 | Z59: KSSM132 132.00 | AA59: T2 | AB59: KSSM132 | AD59: KSSM132T2 | AE59: 5.3515 | AF59: 61135 | AH59: KRYG132T2
A60: 132/33kV T1 & T3 & T5 | B60: 1T0 & 3T0 & 5T0 | C60: 82.5745 | E60: KBRU 33kV | H60: =VLOOKUP(AH60,$AD$3:$AF$1300,3,FALSE) -> 74145 | I60: T1 | J60: 49.1 | K60: KRYG132 | M60: =K60&I60 -> KRYG132T1 | N60: =VLOOKUP(H60,'TNB Load'!$A$2:$F$1448,6,FALSE) -> PAHANG | O60: =VLOOKUP(M60,$W$3:$X$1300,2,FALSE) -> 31.6769 | R60: 61135 | S60: KSSM132 132.00 | T60: T3 | U60: =LEFT(S60,7) -> KSSM132 | W60: =U60&T60 -> KSSM132T3 | X60: 12.456 | Z60: KSSM132 132.00 | AA60: T3 | AB60: KSSM132 | AD60: KSSM132T3 | AE60: 12.456 | AF60: 61135 | AH60: KRYG132T1
A61: 132/33kV T1 & T2 | B61: 1T0 & 2T0 | C61: 65.7207 | E61: PJST 33 kV | H61: =VLOOKUP(AH61,$AD$3:$AF$1300,3,FALSE) -> 96141 | I61: F2 | J61: 49.1 | K61: SHEL132 | M61: =K61&I61 -> SHEL132F2 | N61: =VLOOKUP(H61,'TNB Load'!$A$2:$F$1448,6,FALSE) -> NS | O61: =VLOOKUP(M61,$W$3:$X$1300,2,FALSE) -> 19.1541 | R61: 61135 | S61: KSSM132 132.00 | T61: T4 | U61: =LEFT(S61,7) -> KSSM132 | W61: =U61&T61 -> KSSM132T4 | X61: 12.5658 | Z61: KSSM132 132.00 | AA61: T4 | AB61: KSSM132 | AD61: KSSM132T4 | AE61: 12.5658 | AF61: 61135 | AH61: SHEL132F2
A62: 132/33kV T1 & T2 | B62: 1T0 & 2T0 | C62: 111.1269 | E62: PGTC 33kV | H62: =VLOOKUP(AH62,$AD$3:$AF$1300,3,FALSE) -> 96141 | I62: F1 | J62: 49.1 | K62: SHEL132 | M62: =K62&I62 -> SHEL132F1 | N62: =VLOOKUP(H62,'TNB Load'!$A$2:$F$1448,6,FALSE) -> NS | O62: =VLOOKUP(M62,$W$3:$X$1300,2,FALSE) -> 18.1541 | R62: 561111 | S62: KSTR132R 132.00 | T62: T8 | U62: =LEFT(S62,7) -> KSTR132 | W62: =U62&T62 -> KSTR132T8 | X62: 26.6486 | Z62: KSTR132R 132.00 | AA62: T8 | AB62: KSTR132 | AD62: KSTR132T8 | AE62: 26.6486 | AF62: 561111 | AH62: SHEL132F1
A63: 132/22kV T1 & T2 | B63: 1T0 & 2T0 | C63: 37.2708 | E63: PGIE 22kV | H63: =VLOOKUP(AH63,$AD$3:$AF$1300,3,FALSE) -> 51072 | I63: T2 | J63: 49.1 | K63: HCOM132 | M63: =K63&I63 -> HCOM132T2 | N63: =VLOOKUP(H63,'TNB Load'!$A$2:$F$1448,6,FALSE) -> SELANGOR | O63: =VLOOKUP(M63,$W$3:$X$1300,2,FALSE) -> 34.0078 | R63: 161111 | S63: KSTR_T 132.00 | T63: T7 | U63: =LEFT(S63,7) -> KSTR_T | W63: =U63&T63 -> KSTR_T T7 | X63: 36.2766 | Z63: KSTR_T 132.00 | AA63: T7 | AB63: KSTR_T | AD63: KSTR_T T7 | AE63: 36.2766 | AF63: 161111 | AH63: HCOM132T2
...
